Workbook

Sheet Brief
B2: Report Writer Project: Monthly Support Report
B3: From a blank brief to a finished report, every step shown in the workbook. Work left to right through the tabs.
B5: 1. Project brief (step 1: understand what is needed)
B6: Report title | C6: Monthly Customer Support Report
B7: Period start | C7: 46266
B8: Period end | C8: 46295
B9: Audience | C9: Head of Customer Support
B10: Purpose | C10: Show how the support team performed this month and where to improve.
B11: Questions to answer | C11: 1) How many tickets came in and how fast were they resolved? 2) Which categories drive volume? 3) How satisfied are customers, and which agents and weeks stand out?
B12: Data source | C12: Helpdesk ticket export, sample data (see Raw_Data tab)
B13: Prepared by | C13: Your name
B14: Deadline | C14: 46311
B16: 2. Settings and assumptions (change these and the report updates)
B17: Max plausible resolution hours | C17: 168 | D17: Longer than 1 week is treated as a data error and left out of averages.
B18: Target avg resolution hours | C18: 24 | D18: Team target (assumption for this sample project).
B19: Target avg satisfaction (1-5) | C19: 4 | D19: Team target (assumption for this sample project).
B21: 3. Workflow (the 7 stages of a report)
B22: Stage | C22: What you do | D22: Tab | E22: Done?
B23: 1. Understand the brief | C23: Agree audience, period, purpose and the questions the report must answer. | D23: Brief | E23: Yes
B24: 2. Collect raw data | C24: Save the export exactly as received. Never edit it by hand. | D24: Raw_Data | E24: Yes
B25: 3. Clean the data | C25: Fix spaces and capitals, convert text dates, flag duplicates, blank bad values with formulas. | D25: Cleaning | E25: Yes
B26: 4. Check quality | C26: Log every problem found and prove that totals reconcile (PASS/FAIL). | D26: Checks | E26: Yes
B27: 5. Analyse | C27: Build the summary tables (by category, agent, priority, week). | D27: Analysis | E27: Yes
B28: 6. Write the report | C28: Turn the numbers into a one-page report: summary, charts, findings, recommendations. | D28: Report | E28: Yes
B29: 7. Review and deliver | C29: Complete the review checklist, export to PDF and send. | D29: Checks | E29: No
B31: Colour code: blue = input you can change, black = formula, green = link from another tab, yellow = control cell.

Sheet Raw_Data
A1: Ticket ID | B1: Date | C1: Agent | D1: Category | E1: Priority | F1: Status | G1: Resolution Hours | H1: CSAT (1-5) | J1: Raw export as received. It is deliberately messy: extra spaces, mixed capitals, dates stored as text, duplicates, blanks and impossible values. Do not edit; the Cleaning tab fixes everything with formulas.
A2: TKT-1001 | B2: 46266 | C2: Liam O'Brien | D2: Login Issue | E2: Low | F2: Escalated
A3: TKT-1002 | B3: 46266 | C3: sofia rossi | D3: Billing | E3: Medium | F3: Resolved | G3: 57.6 | H3: 3
A4: TKT-1003 | B4: 46266 | C4: Sofia Rossi | D4: Feature Request | E4: Medium | F4: Resolved | G4: 20.1 | H4: 3
A5: TKT-1004 | B5: 46266 | C5: ava johnson | D5: delivery | E5: Urgent | F5: Open
A6: TKT-1005 | B6: 46266 | C6: liam o'brien | D6: Delivery | E6: High | F6: resolved | G6: 7.4 | H6: 5
A7: TKT-1006 | B7: 46266 | C7: Sofia Rossi | D7: Billing | E7: MEDIUM | F7: Resolved | G7: 48.8 | H7: 3
A8: TKT-1007 | B8: 46267 | C8: Sofia Rossi | D8: billing | E8: Low | F8: Resolved | G8: 21
A9: TKT-1008 | B9: 46267 | C9: Sofia Rossi | D9: DELIVERY | E9: Low | F9: resolved | G9: 41.5 | H9: 3
A10: TKT-1009 | B10: 46267 | C10: Sofia Rossi | D10: Billing | E10: Urgent | F10: Resolved | G10: 5.5 | H10: 5
A11: TKT-1010 | B11: 46267 | C11: maya patel | D11: Billing | E11: URGENT | F11: RESOLVED | G11: 3.8 | H11: 5
A12: TKT-1011 | B12: 46267 | C12: Maya Patel | D12: Delivery | E12: high | F12: Resolved | G12: 11.5 | H12: 5
A13: TKT-1012 | B13: 46267 | C13: Maya Patel | D13: Billing | E13: Low | F13: Resolved | G13: 24.3 | H13: 4
A14: TKT-1013 | B14: 46267 | C14: Liam O'Brien | D14: Billing | E14: High | F14: OPEN
A15: TKT-1014 | B15: 46267 | C15: Ava Johnson | D15: Delivery | E15: Medium | F15: Open
A16: TKT-1015 | B16: 46267 | C16: Ava Johnson | D16: Billing | E16: low | F16: resolved | G16: 23.3 | H16: 4
A17: TKT-1016 | B17: 46267 | C17: Maya Patel | D17: Bug Report | E17: Medium | F17: Resolved | G17: 18.7
A18: TKT-1017 | B18: 46267 | C18: Ava Johnson | D18: billing | E18: Low | F18: Resolved | G18: 8.2
A19: TKT-1018 | B19: 46267 | C19: sofia rossi | D19: Bug Report | E19: Medium | F19: Resolved | G19: 25.4 | H19: 4
A20: TKT-1019 | B20: 46267 | C20: Noah Kim | D20: Login Issue | E20: Low | F20: resolved | G20: 13.9 | H20: 4
A21: TKT-1020 | B21: 46268 | C21: liam o'brien | D21: login issue | E21: Low | F21: RESOLVED | G21: 15.1 | H21: 5
A22: TKT-1021 | B22: 46268 | C22: Noah Kim | D22: billing | E22: URGENT | F22: Resolved | G22: 1.7 | H22: 5
A23: TKT-1022 | B23: 46268 | C23: Ava Johnson | D23: Login Issue | E23: Medium | F23: Resolved | G23: 6 | H23: 4
A24: TKT-1023 | B24: 46268 | C24: Noah Kim | D24: Login Issue | E24: Low | F24: resolved | G24: 27.4 | H24: 5
A25: TKT-1024 | B25: 46268 | C25: Maya Patel | D25: billing | E25: Low | F25: Open
A26: TKT-1025 | B26: 46268 | C26: Liam O'Brien | D26: BILLING | E26: Low | F26: Resolved | G26: 999 | H26: 5
A27: TKT-1026 | B27: 46268 | C27: Ava Johnson | D27: Login Issue | E27: Medium | F27: RESOLVED | G27: 14.4
A28: TKT-1027 | B28: 2026-09-03 | C28: Maya Patel | D28: Delivery | E28: Low | F28: OPEN
A29: TKT-1028 | B29: 46268 | C29: maya patel | D29: BILLING | E29: Low | F29: Resolved | G29: 45.6 | H29: 3
A30: TKT-1029 | B30: 46269 | C30: ava johnson | D30: BILLING | E30: Medium | F30: Resolved | G30: 7 | H30: 5
A31: TKT-1030 | B31: 46269 | C31: Sofia Rossi | D31: Bug Report | E31: Low | F31: RESOLVED | G31: 33.7 | H31: 4
A32: TKT-1031 | B32: 46269 | C32: Sofia Rossi | D32: billing | E32: Low | F32: resolved | G32: 64 | H32: 2
A33: TKT-1032 | B33: 46269 | C33: Noah Kim | D33: Bug Report | E33: Medium | F33: open
A34: TKT-1033 | B34: 46269 | C34: AVA JOHNSON | D34: Login Issue | E34: Low | F34: Resolved | G34: 19.3 | H34: 5
A35: TKT-1034 | B35: 46269 | C35: MAYA PATEL | D35: Delivery | E35: Low | F35: Resolved | G35: 39 | H35: 4
A36: TKT-1035 | B36: 46269 | C36: Ava Johnson | D36: Bug Report | E36: low | F36: resolved | G36: 11.1 | H36: 5
A37: TKT-1036 | B37: 46269 | C37: Noah Kim | D37: Billing | E37: Medium | F37: resolved | G37: 27.7 | H37: 5
A38: TKT-1037 | B38: 46269 | C38: liam o'brien | D38: Billing | E38: Medium | F38: Resolved | G38: 12 | H38: 5
A39: TKT-1038 | B39: 2026-09-05 | C39: Maya Patel | D39: BILLING | E39: High | F39: Resolved | G39: 10.2
A40: TKT-1039 | B40: 2026-09-05 | C40: Ava Johnson | D40: Delivery | E40: Low | F40: open
...

Sheet Cleaning
A1: Ticket ID | B1: Date | C1: Agent | D1: Category | E1: Priority | F1: Status | G1: Hours | H1: CSAT | I1: Duplicate? | J1: Date fix | K1: Hours issue | L1: Keep (1/0) | N1: Every cell here is a formula pointing at Raw_Data. Red rows are duplicates (Keep = 0). To refresh with a new export, paste it over Raw_Data and copy the formulas down.
A2: =TRIM(Raw_Data!A2) -> TKT-1001 | B2: =IF(ISNUMBER(Raw_Data!B2),Raw_Data!B2,DATEVALUE(TRIM(Raw_Data!B2))) -> 46266 | C2: =PROPER(TRIM(Raw_Data!C2)) -> Liam O'Brien | D2: =PROPER(TRIM(Raw_Data!D2)) -> Login Issue | E2: =PROPER(TRIM(Raw_Data!E2)) -> Low | F2: =PROPER(TRIM(Raw_Data!F2)) -> Escalated | G2: =IF(Raw_Data!G2="","",IF(Raw_Data!G2>Brief!$C$17,"",Raw_Data!G2)) | H2: =IF(Raw_Data!H2="","",Raw_Data!H2) | I2: =IF(COUNTIF($A$2:A2,A2)>1,"Duplicate","OK") -> OK | J2: =IF(ISNUMBER(Raw_Data!B2),"","Text date fixed") | K2: =IF(Raw_Data!G2="",IF(F2="Resolved","Missing hours",""),IF(Raw_Data!G2>Brief!$C$17,"Outlier removed","")) | L2: =IF(I2="OK",1,0) -> 1
A3: =TRIM(Raw_Data!A3) -> TKT-1002 | B3: =IF(ISNUMBER(Raw_Data!B3),Raw_Data!B3,DATEVALUE(TRIM(Raw_Data!B3))) -> 46266 | C3: =PROPER(TRIM(Raw_Data!C3)) -> Sofia Rossi | D3: =PROPER(TRIM(Raw_Data!D3)) -> Billing | E3: =PROPER(TRIM(Raw_Data!E3)) -> Medium | F3: =PROPER(TRIM(Raw_Data!F3)) -> Resolved | G3: =IF(Raw_Data!G3="","",IF(Raw_Data!G3>Brief!$C$17,"",Raw_Data!G3)) -> 57.6 | H3: =IF(Raw_Data!H3="","",Raw_Data!H3) -> 3 | I3: =IF(COUNTIF($A$2:A3,A3)>1,"Duplicate","OK") -> OK | J3: =IF(ISNUMBER(Raw_Data!B3),"","Text date fixed") | K3: =IF(Raw_Data!G3="",IF(F3="Resolved","Missing hours",""),IF(Raw_Data!G3>Brief!$C$17,"Outlier removed","")) | L3: =IF(I3="OK",1,0) -> 1
A4: =TRIM(Raw_Data!A4) -> TKT-1003 | B4: =IF(ISNUMBER(Raw_Data!B4),Raw_Data!B4,DATEVALUE(TRIM(Raw_Data!B4))) -> 46266 | C4: =PROPER(TRIM(Raw_Data!C4)) -> Sofia Rossi | D4: =PROPER(TRIM(Raw_Data!D4)) -> Feature Request | E4: =PROPER(TRIM(Raw_Data!E4)) -> Medium | F4: =PROPER(TRIM(Raw_Data!F4)) -> Resolved | G4: =IF(Raw_Data!G4="","",IF(Raw_Data!G4>Brief!$C$17,"",Raw_Data!G4)) -> 20.1 | H4: =IF(Raw_Data!H4="","",Raw_Data!H4) -> 3 | I4: =IF(COUNTIF($A$2:A4,A4)>1,"Duplicate","OK") -> OK | J4: =IF(ISNUMBER(Raw_Data!B4),"","Text date fixed") | K4: =IF(Raw_Data!G4="",IF(F4="Resolved","Missing hours",""),IF(Raw_Data!G4>Brief!$C$17,"Outlier removed","")) | L4: =IF(I4="OK",1,0) -> 1
A5: =TRIM(Raw_Data!A5) -> TKT-1004 | B5: =IF(ISNUMBER(Raw_Data!B5),Raw_Data!B5,DATEVALUE(TRIM(Raw_Data!B5))) -> 46266 | C5: =PROPER(TRIM(Raw_Data!C5)) -> Ava Johnson | D5: =PROPER(TRIM(Raw_Data!D5)) -> Delivery | E5: =PROPER(TRIM(Raw_Data!E5)) -> Urgent | F5: =PROPER(TRIM(Raw_Data!F5)) -> Open | G5: =IF(Raw_Data!G5="","",IF(Raw_Data!G5>Brief!$C$17,"",Raw_Data!G5)) | H5: =IF(Raw_Data!H5="","",Raw_Data!H5) | I5: =IF(COUNTIF($A$2:A5,A5)>1,"Duplicate","OK") -> OK | J5: =IF(ISNUMBER(Raw_Data!B5),"","Text date fixed") | K5: =IF(Raw_Data!G5="",IF(F5="Resolved","Missing hours",""),IF(Raw_Data!G5>Brief!$C$17,"Outlier removed","")) | L5: =IF(I5="OK",1,0) -> 1
A6: =TRIM(Raw_Data!A6) -> TKT-1005 | B6: =IF(ISNUMBER(Raw_Data!B6),Raw_Data!B6,DATEVALUE(TRIM(Raw_Data!B6))) -> 46266 | C6: =PROPER(TRIM(Raw_Data!C6)) -> Liam O'Brien | D6: =PROPER(TRIM(Raw_Data!D6)) -> Delivery | E6: =PROPER(TRIM(Raw_Data!E6)) -> High | F6: =PROPER(TRIM(Raw_Data!F6)) -> Resolved | G6: =IF(Raw_Data!G6="","",IF(Raw_Data!G6>Brief!$C$17,"",Raw_Data!G6)) -> 7.4 | H6: =IF(Raw_Data!H6="","",Raw_Data!H6) -> 5 | I6: =IF(COUNTIF($A$2:A6,A6)>1,"Duplicate","OK") -> OK | J6: =IF(ISNUMBER(Raw_Data!B6),"","Text date fixed") | K6: =IF(Raw_Data!G6="",IF(F6="Resolved","Missing hours",""),IF(Raw_Data!G6>Brief!$C$17,"Outlier removed","")) | L6: =IF(I6="OK",1,0) -> 1
A7: =TRIM(Raw_Data!A7) -> TKT-1006 | B7: =IF(ISNUMBER(Raw_Data!B7),Raw_Data!B7,DATEVALUE(TRIM(Raw_Data!B7))) -> 46266 | C7: =PROPER(TRIM(Raw_Data!C7)) -> Sofia Rossi | D7: =PROPER(TRIM(Raw_Data!D7)) -> Billing | E7: =PROPER(TRIM(Raw_Data!E7)) -> Medium | F7: =PROPER(TRIM(Raw_Data!F7)) -> Resolved | G7: =IF(Raw_Data!G7="","",IF(Raw_Data!G7>Brief!$C$17,"",Raw_Data!G7)) -> 48.8 | H7: =IF(Raw_Data!H7="","",Raw_Data!H7) -> 3 | I7: =IF(COUNTIF($A$2:A7,A7)>1,"Duplicate","OK") -> OK | J7: =IF(ISNUMBER(Raw_Data!B7),"","Text date fixed") | K7: =IF(Raw_Data!G7="",IF(F7="Resolved","Missing hours",""),IF(Raw_Data!G7>Brief!$C$17,"Outlier removed","")) | L7: =IF(I7="OK",1,0) -> 1
A8: =TRIM(Raw_Data!A8) -> TKT-1007 | B8: =IF(ISNUMBER(Raw_Data!B8),Raw_Data!B8,DATEVALUE(TRIM(Raw_Data!B8))) -> 46267 | C8: =PROPER(TRIM(Raw_Data!C8)) -> Sofia Rossi | D8: =PROPER(TRIM(Raw_Data!D8)) -> Billing | E8: =PROPER(TRIM(Raw_Data!E8)) -> Low | F8: =PROPER(TRIM(Raw_Data!F8)) -> Resolved | G8: =IF(Raw_Data!G8="","",IF(Raw_Data!G8>Brief!$C$17,"",Raw_Data!G8)) -> 21 | H8: =IF(Raw_Data!H8="","",Raw_Data!H8) | I8: =IF(COUNTIF($A$2:A8,A8)>1,"Duplicate","OK") -> OK | J8: =IF(ISNUMBER(Raw_Data!B8),"","Text date fixed") | K8: =IF(Raw_Data!G8="",IF(F8="Resolved","Missing hours",""),IF(Raw_Data!G8>Brief!$C$17,"Outlier removed","")) | L8: =IF(I8="OK",1,0) -> 1
A9: =TRIM(Raw_Data!A9) -> TKT-1008 | B9: =IF(ISNUMBER(Raw_Data!B9),Raw_Data!B9,DATEVALUE(TRIM(Raw_Data!B9))) -> 46267 | C9: =PROPER(TRIM(Raw_Data!C9)) -> Sofia Rossi | D9: =PROPER(TRIM(Raw_Data!D9)) -> Delivery | E9: =PROPER(TRIM(Raw_Data!E9)) -> Low | F9: =PROPER(TRIM(Raw_Data!F9)) -> Resolved | G9: =IF(Raw_Data!G9="","",IF(Raw_Data!G9>Brief!$C$17,"",Raw_Data!G9)) -> 41.5 | H9: =IF(Raw_Data!H9="","",Raw_Data!H9) -> 3 | I9: =IF(COUNTIF($A$2:A9,A9)>1,"Duplicate","OK") -> OK | J9: =IF(ISNUMBER(Raw_Data!B9),"","Text date fixed") | K9: =IF(Raw_Data!G9="",IF(F9="Resolved","Missing hours",""),IF(Raw_Data!G9>Brief!$C$17,"Outlier removed","")) | L9: =IF(I9="OK",1,0) -> 1
A10: =TRIM(Raw_Data!A10) -> TKT-1009 | B10: =IF(ISNUMBER(Raw_Data!B10),Raw_Data!B10,DATEVALUE(TRIM(Raw_Data!B10))) -> 46267 | C10: =PROPER(TRIM(Raw_Data!C10)) -> Sofia Rossi | D10: =PROPER(TRIM(Raw_Data!D10)) -> Billing | E10: =PROPER(TRIM(Raw_Data!E10)) -> Urgent | F10: =PROPER(TRIM(Raw_Data!F10)) -> Resolved | G10: =IF(Raw_Data!G10="","",IF(Raw_Data!G10>Brief!$C$17,"",Raw_Data!G10)) -> 5.5 | H10: =IF(Raw_Data!H10="","",Raw_Data!H10) -> 5 | I10: =IF(COUNTIF($A$2:A10,A10)>1,"Duplicate","OK") -> OK | J10: =IF(ISNUMBER(Raw_Data!B10),"","Text date fixed") | K10: =IF(Raw_Data!G10="",IF(F10="Resolved","Missing hours",""),IF(Raw_Data!G10>Brief!$C$17,"Outlier removed","")) | L10: =IF(I10="OK",1,0) -> 1
A11: =TRIM(Raw_Data!A11) -> TKT-1010 | B11: =IF(ISNUMBER(Raw_Data!B11),Raw_Data!B11,DATEVALUE(TRIM(Raw_Data!B11))) -> 46267 | C11: =PROPER(TRIM(Raw_Data!C11)) -> Maya Patel | D11: =PROPER(TRIM(Raw_Data!D11)) -> Billing | E11: =PROPER(TRIM(Raw_Data!E11)) -> Urgent | F11: =PROPER(TRIM(Raw_Data!F11)) -> Resolved | G11: =IF(Raw_Data!G11="","",IF(Raw_Data!G11>Brief!$C$17,"",Raw_Data!G11)) -> 3.8 | H11: =IF(Raw_Data!H11="","",Raw_Data!H11) -> 5 | I11: =IF(COUNTIF($A$2:A11,A11)>1,"Duplicate","OK") -> OK | J11: =IF(ISNUMBER(Raw_Data!B11),"","Text date fixed") | K11: =IF(Raw_Data!G11="",IF(F11="Resolved","Missing hours",""),IF(Raw_Data!G11>Brief!$C$17,"Outlier removed","")) | L11: =IF(I11="OK",1,0) -> 1
A12: =TRIM(Raw_Data!A12) -> TKT-1011 | B12: =IF(ISNUMBER(Raw_Data!B12),Raw_Data!B12,DATEVALUE(TRIM(Raw_Data!B12))) -> 46267 | C12: =PROPER(TRIM(Raw_Data!C12)) -> Maya Patel | D12: =PROPER(TRIM(Raw_Data!D12)) -> Delivery | E12: =PROPER(TRIM(Raw_Data!E12)) -> High | F12: =PROPER(TRIM(Raw_Data!F12)) -> Resolved | G12: =IF(Raw_Data!G12="","",IF(Raw_Data!G12>Brief!$C$17,"",Raw_Data!G12)) -> 11.5 | H12: =IF(Raw_Data!H12="","",Raw_Data!H12) -> 5 | I12: =IF(COUNTIF($A$2:A12,A12)>1,"Duplicate","OK") -> OK | J12: =IF(ISNUMBER(Raw_Data!B12),"","Text date fixed") | K12: =IF(Raw_Data!G12="",IF(F12="Resolved","Missing hours",""),IF(Raw_Data!G12>Brief!$C$17,"Outlier removed","")) | L12: =IF(I12="OK",1,0) -> 1
A13: =TRIM(Raw_Data!A13) -> TKT-1012 | B13: =IF(ISNUMBER(Raw_Data!B13),Raw_Data!B13,DATEVALUE(TRIM(Raw_Data!B13))) -> 46267 | C13: =PROPER(TRIM(Raw_Data!C13)) -> Maya Patel | D13: =PROPER(TRIM(Raw_Data!D13)) -> Billing | E13: =PROPER(TRIM(Raw_Data!E13)) -> Low | F13: =PROPER(TRIM(Raw_Data!F13)) -> Resolved | G13: =IF(Raw_Data!G13="","",IF(Raw_Data!G13>Brief!$C$17,"",Raw_Data!G13)) -> 24.3 | H13: =IF(Raw_Data!H13="","",Raw_Data!H13) -> 4 | I13: =IF(COUNTIF($A$2:A13,A13)>1,"Duplicate","OK") -> OK | J13: =IF(ISNUMBER(Raw_Data!B13),"","Text date fixed") | K13: =IF(Raw_Data!G13="",IF(F13="Resolved","Missing hours",""),IF(Raw_Data!G13>Brief!$C$17,"Outlier removed","")) | L13: =IF(I13="OK",1,0) -> 1
... A157: =TRIM(Raw_Data!A157) -> TKT-1042 | B157: =IF(ISNUMBER(Raw_Data!B157),Raw_Data!B157,DATEVALUE(TRIM(Raw_Data!B157))) -> 46272 | C157: =PROPER(TRIM(Raw_Data!C157)) -> Noah Kim | D157: =PROPER(TRIM(Raw_Data!D157)) -> Delivery | E157: =PROPER(TRIM(Raw_Data!E157)) -> High | F157: =PROPER(TRIM(Raw_Data!F157)) -> Resolved | G157: =IF(Raw_Data!G157="","",IF(Raw_Data!G157>Brief!$C$17,"",Raw_Data!G157)) -> 9.4 | H157: =IF(Raw_Data!H157="","",Raw_Data!H157) -> 5 | I157: =IF(COUNTIF($A$2:A157,A157)>1,"Duplicate","OK") -> Duplicate | J157: =IF(ISNUMBER(Raw_Data!B157),"","Text date fixed") | K157: =IF(Raw_Data!G157="",IF(F157="Resolved","Missing hours",""),IF(Raw_Data!G157>Brief!$C$17,"Outlier removed","")) | L157: =IF(I157="OK",1,0) -> 0

Sheet Checks
B2: Quality checks (step 4 and step 7)
B4: A. Data quality log: what was wrong with the raw export
B5: Issue | C5: Count | D5: What was done
B6: Rows received | C6: =COUNTA(Raw_Data!$A$2:$A$500) -> 156 | D6: Rows in the raw export
B7: Duplicate tickets | C7: =COUNTIF(Cleaning!$I$2:$I$500,"Duplicate") -> 6 | D7: Excluded from the report (Keep = 0)
B8: Dates stored as text | C8: =COUNTIF(Cleaning!$J$2:$J$500,"Text date fixed") -> 10 | D8: Converted to real dates
B9: Resolution time missing | C9: =COUNTIF(Cleaning!$K$2:$K$500,"Missing hours") -> 4 | D9: Resolved tickets with no time; left out of averages
B10: Resolution time impossible | C10: =COUNTIF(Cleaning!$K$2:$K$500,"Outlier removed") -> 2 | D10: Above the maximum on the Brief tab; left out of averages
B11: Satisfaction score missing | C11: =COUNTIFS(Cleaning!$F$2:$F$500,"Resolved",Cleaning!$L$2:$L$500,1)-COUNTIFS(Cleaning!$F$2:$F$500,"Resolved",Cleaning!$L$2:$L$500,1,Cleaning!$H$2:$H$500,">0") -> 18 | D11: Resolved tickets with no score; left out of averages
B12: Rows used in the report | C12: =SUM(Cleaning!$L$2:$L$500) -> 150 | D12: Unique tickets
B14: B. Reconciliation checks: do the totals agree?
B15: Check | C15: Expected | D15: Actual | E15: Result
B16: Received minus duplicates = rows used | C16: =C6-C7 -> 150 | D16: =C12 -> 150 | E16: =IF(D16=C16,"PASS","FAIL") -> PASS
B17: Category table adds up to rows used | C17: =C12 -> 150 | D17: =Analysis!B21 -> 150 | E17: =IF(D17=C17,"PASS","FAIL") -> PASS
B18: Agent table adds up to rows used | C18: =C12 -> 150 | D18: =Analysis!B31 -> 150 | E18: =IF(D18=C18,"PASS","FAIL") -> PASS
B19: Priority table adds up to rows used | C19: =C12 -> 150 | D19: =Analysis!B40 -> 150 | E19: =IF(D19=C19,"PASS","FAIL") -> PASS
B20: Weekly table adds up to rows used | C20: =C12 -> 150 | D20: =Analysis!I10 -> 150 | E20: =IF(D20=C20,"PASS","FAIL") -> PASS
B21: Report headline tickets = Analysis | C21: =Analysis!B4 -> 150 | D21: =Report!B11 -> 150 | E21: =IF(D21=C21,"PASS","FAIL") -> PASS
B22: Kept tickets dated outside the period | C22: =0 -> 0 | D22: =COUNTIFS(Cleaning!$L$2:$L$500,1,Cleaning!$B$2:$B$500,"<"&Brief!$C$7)+COUNTIFS(Cleaning!$L$2:$L$500,1,Cleaning!$B$2:$B$500,">"&Brief!$C$8) -> 0 | E22: =IF(D22=C22,"PASS","FAIL") -> PASS
B24: Overall status | C24: =IF(COUNTIF(E16:E22,"FAIL")=0,"ALL CHECKS PASS","CHECK FAILED") -> ALL CHECKS PASS
B26: C. Review checklist (tick off before sending)
B27: Item | C27: Done?
B28: Numbers checked against the source system | C28: No
B29: Spelling and grammar reviewed | C29: No
B30: Chart titles and labels read out loud | C30: No
B31: Peer review completed | C31: No
B32: Report exported to PDF | C32: No
B33: Report sent to the audience | C33: No

Sheet Analysis
A1: Analysis tables (step 5)
A3: Headline KPIs | G3: Weekly volume
A4: Total tickets | B4: =SUM(Cleaning!$L$2:$L$500) -> 150 | G4: Week | H4: Dates | I4: Tickets | J4: Start | K4: End
A5: Resolved | B5: =COUNTIFS(Cleaning!$F$2:$F$500,"Resolved",Cleaning!$L$2:$L$500,1) -> 124 | G5: Week 1 | H5: =TEXT(J5,"d mmm")&" - "&TEXT(K5,"d mmm") -> 1 Sep - 7 Sep | I5: =COUNTIFS(Cleaning!$B$2:$B$500,">="&J5,Cleaning!$B$2:$B$500,"<="&K5,Cleaning!$L$2:$L$500,1) -> 43 | J5: =Brief!$C$7 -> 46266 | K5: =MIN(J5+6,Brief!$C$8) -> 46272
A6: Resolution rate | B6: =IF(B4=0,0,B5/B4) -> 0.82666667 | G6: Week 2 | H6: =TEXT(J6,"d mmm")&" - "&TEXT(K6,"d mmm") -> 8 Sep - 14 Sep | I6: =COUNTIFS(Cleaning!$B$2:$B$500,">="&J6,Cleaning!$B$2:$B$500,"<="&K6,Cleaning!$L$2:$L$500,1) -> 39 | J6: =K5+1 -> 46273 | K6: =MIN(J6+6,Brief!$C$8) -> 46279
A7: Open | B7: =COUNTIFS(Cleaning!$F$2:$F$500,"Open",Cleaning!$L$2:$L$500,1) -> 15 | G7: Week 3 | H7: =TEXT(J7,"d mmm")&" - "&TEXT(K7,"d mmm") -> 15 Sep - 21 Sep | I7: =COUNTIFS(Cleaning!$B$2:$B$500,">="&J7,Cleaning!$B$2:$B$500,"<="&K7,Cleaning!$L$2:$L$500,1) -> 33 | J7: =K6+1 -> 46280 | K7: =MIN(J7+6,Brief!$C$8) -> 46286
A8: Escalated | B8: =COUNTIFS(Cleaning!$F$2:$F$500,"Escalated",Cleaning!$L$2:$L$500,1) -> 11 | G8: Week 4 | H8: =TEXT(J8,"d mmm")&" - "&TEXT(K8,"d mmm") -> 22 Sep - 28 Sep | I8: =COUNTIFS(Cleaning!$B$2:$B$500,">="&J8,Cleaning!$B$2:$B$500,"<="&K8,Cleaning!$L$2:$L$500,1) -> 27 | J8: =K7+1 -> 46287 | K8: =MIN(J8+6,Brief!$C$8) -> 46293
A9: Avg resolution hours | B9: =IFERROR(AVERAGEIFS(Cleaning!$G$2:$G$500,Cleaning!$L$2:$L$500,1),0) -> 18.128814 | G9: Week 5 | H9: =TEXT(J9,"d mmm")&" - "&TEXT(K9,"d mmm") -> 29 Sep - 30 Sep | I9: =COUNTIFS(Cleaning!$B$2:$B$500,">="&J9,Cleaning!$B$2:$B$500,"<="&K9,Cleaning!$L$2:$L$500,1) -> 8 | J9: =K8+1 -> 46294 | K9: =MIN(J9+6,Brief!$C$8) -> 46295
A10: Avg satisfaction (1-5) | B10: =IFERROR(AVERAGEIFS(Cleaning!$H$2:$H$500,Cleaning!$L$2:$L$500,1),0) -> 4.1226415 | G10: Total | I10: =SUM(I5:I9) -> 150
A11: High + Urgent share | B11: =IF(B4=0,0,(COUNTIFS(Cleaning!$E$2:$E$500,"High",Cleaning!$L$2:$L$500,1)+COUNTIFS(Cleaning!$E$2:$E$500,"Urgent",Cleaning!$L$2:$L$500,1))/B4) -> 0.26
G13: By status
A14: By category | G14: Status | H14: Tickets | I14: Share
A15: Category | B15: Tickets | C15: Share | D15: Avg hours | E15: Avg CSAT | G15: Resolved | H15: =COUNTIFS(Cleaning!$F$2:$F$500,G15,Cleaning!$L$2:$L$500,1) -> 124 | I15: =IF($H$18=0,0,H15/$H$18) -> 0.82666667
A16: Billing | B16: =COUNTIFS(Cleaning!$D$2:$D$500,A16,Cleaning!$L$2:$L$500,1) -> 61 | C16: =IF($B$21=0,0,B16/$B$21) -> 0.40666667 | D16: =IFERROR(AVERAGEIFS(Cleaning!$G$2:$G$500,Cleaning!$D$2:$D$500,A16,Cleaning!$L$2:$L$500,1),0) -> 18.339623 | E16: =IFERROR(AVERAGEIFS(Cleaning!$H$2:$H$500,Cleaning!$D$2:$D$500,A16,Cleaning!$L$2:$L$500,1),0) -> 4.0833333 | G16: Open | H16: =COUNTIFS(Cleaning!$F$2:$F$500,G16,Cleaning!$L$2:$L$500,1) -> 15 | I16: =IF($H$18=0,0,H16/$H$18) -> 0.1
A17: Login Issue | B17: =COUNTIFS(Cleaning!$D$2:$D$500,A17,Cleaning!$L$2:$L$500,1) -> 25 | C17: =IF($B$21=0,0,B17/$B$21) -> 0.16666667 | D17: =IFERROR(AVERAGEIFS(Cleaning!$G$2:$G$500,Cleaning!$D$2:$D$500,A17,Cleaning!$L$2:$L$500,1),0) -> 16.666667 | E17: =IFERROR(AVERAGEIFS(Cleaning!$H$2:$H$500,Cleaning!$D$2:$D$500,A17,Cleaning!$L$2:$L$500,1),0) -> 4.2941176 | G17: Escalated | H17: =COUNTIFS(Cleaning!$F$2:$F$500,G17,Cleaning!$L$2:$L$500,1) -> 11 | I17: =IF($H$18=0,0,H17/$H$18) -> 0.073333333
A18: Bug Report | B18: =COUNTIFS(Cleaning!$D$2:$D$500,A18,Cleaning!$L$2:$L$500,1) -> 25 | C18: =IF($B$21=0,0,B18/$B$21) -> 0.16666667 | D18: =IFERROR(AVERAGEIFS(Cleaning!$G$2:$G$500,Cleaning!$D$2:$D$500,A18,Cleaning!$L$2:$L$500,1),0) -> 19.984211 | E18: =IFERROR(AVERAGEIFS(Cleaning!$H$2:$H$500,Cleaning!$D$2:$D$500,A18,Cleaning!$L$2:$L$500,1),0) -> 4.2666667 | G18: Total | H18: =SUM(H15:H17) -> 150 | I18: =SUM(I15:I17) -> 1
A19: Delivery | B19: =COUNTIFS(Cleaning!$D$2:$D$500,A19,Cleaning!$L$2:$L$500,1) -> 28 | C19: =IF($B$21=0,0,B19/$B$21) -> 0.18666667 | D19: =IFERROR(AVERAGEIFS(Cleaning!$G$2:$G$500,Cleaning!$D$2:$D$500,A19,Cleaning!$L$2:$L$500,1),0) -> 17.32 | E19: =IFERROR(AVERAGEIFS(Cleaning!$H$2:$H$500,Cleaning!$D$2:$D$500,A19,Cleaning!$L$2:$L$500,1),0) -> 4.1666667
A20: Feature Request | B20: =COUNTIFS(Cleaning!$D$2:$D$500,A20,Cleaning!$L$2:$L$500,1) -> 11 | C20: =IF($B$21=0,0,B20/$B$21) -> 0.073333333 | D20: =IFERROR(AVERAGEIFS(Cleaning!$G$2:$G$500,Cleaning!$D$2:$D$500,A20,Cleaning!$L$2:$L$500,1),0) -> 17.6375 | E20: =IFERROR(AVERAGEIFS(Cleaning!$H$2:$H$500,Cleaning!$D$2:$D$500,A20,Cleaning!$L$2:$L$500,1),0) -> 3.625
A21: Total | B21: =SUM(B16:B20) -> 150 | C21: =SUM(C16:C20) -> 1 | D21: =B9 -> 18.128814 | E21: =B10 -> 4.1226415
A24: By agent
A25: Agent | B25: Tickets | C25: Resolved | D25: Avg hours | E25: Avg CSAT
A26: Maya Patel | B26: =COUNTIFS(Cleaning!$C$2:$C$500,A26,Cleaning!$L$2:$L$500,1) -> 39 | C26: =COUNTIFS(Cleaning!$C$2:$C$500,A26,Cleaning!$F$2:$F$500,"Resolved",Cleaning!$L$2:$L$500,1) -> 34 | D26: =IFERROR(AVERAGEIFS(Cleaning!$G$2:$G$500,Cleaning!$C$2:$C$500,A26,Cleaning!$L$2:$L$500,1),0) -> 17.333333 | E26: =IFERROR(AVERAGEIFS(Cleaning!$H$2:$H$500,Cleaning!$C$2:$C$500,A26,Cleaning!$L$2:$L$500,1),0) -> 4.1071429
A27: Liam O'Brien | B27: =COUNTIFS(Cleaning!$C$2:$C$500,A27,Cleaning!$L$2:$L$500,1) -> 23 | C27: =COUNTIFS(Cleaning!$C$2:$C$500,A27,Cleaning!$F$2:$F$500,"Resolved",Cleaning!$L$2:$L$500,1) -> 21 | D27: =IFERROR(AVERAGEIFS(Cleaning!$G$2:$G$500,Cleaning!$C$2:$C$500,A27,Cleaning!$L$2:$L$500,1),0) -> 14.875 | E27: =IFERROR(AVERAGEIFS(Cleaning!$H$2:$H$500,Cleaning!$C$2:$C$500,A27,Cleaning!$L$2:$L$500,1),0) -> 4.2380952
A28: Sofia Rossi | B28: =COUNTIFS(Cleaning!$C$2:$C$500,A28,Cleaning!$L$2:$L$500,1) -> 30 | C28: =COUNTIFS(Cleaning!$C$2:$C$500,A28,Cleaning!$F$2:$F$500,"Resolved",Cleaning!$L$2:$L$500,1) -> 24 | D28: =IFERROR(AVERAGEIFS(Cleaning!$G$2:$G$500,Cleaning!$C$2:$C$500,A28,Cleaning!$L$2:$L$500,1),0) -> 30.6 | E28: =IFERROR(AVERAGEIFS(Cleaning!$H$2:$H$500,Cleaning!$C$2:$C$500,A28,Cleaning!$L$2:$L$500,1),0) -> 3.6842105
A29: Noah Kim | B29: =COUNTIFS(Cleaning!$C$2:$C$500,A29,Cleaning!$L$2:$L$500,1) -> 31 | C29: =COUNTIFS(Cleaning!$C$2:$C$500,A29,Cleaning!$F$2:$F$500,"Resolved",Cleaning!$L$2:$L$500,1) -> 24 | D29: =IFERROR(AVERAGEIFS(Cleaning!$G$2:$G$500,Cleaning!$C$2:$C$500,A29,Cleaning!$L$2:$L$500,1),0) -> 16.320833 | E29: =IFERROR(AVERAGEIFS(Cleaning!$H$2:$H$500,Cleaning!$C$2:$C$500,A29,Cleaning!$L$2:$L$500,1),0) -> 4.2857143
A30: Ava Johnson | B30: =COUNTIFS(Cleaning!$C$2:$C$500,A30,Cleaning!$L$2:$L$500,1) -> 27 | C30: =COUNTIFS(Cleaning!$C$2:$C$500,A30,Cleaning!$F$2:$F$500,"Resolved",Cleaning!$L$2:$L$500,1) -> 21 | D30: =IFERROR(AVERAGEIFS(Cleaning!$G$2:$G$500,Cleaning!$C$2:$C$500,A30,Cleaning!$L$2:$L$500,1),0) -> 12.666667 | E30: =IFERROR(AVERAGEIFS(Cleaning!$H$2:$H$500,Cleaning!$C$2:$C$500,A30,Cleaning!$L$2:$L$500,1),0) -> 4.2941176
A31: Total | B31: =SUM(B26:B30) -> 150 | C31: =SUM(C26:C30) -> 124 | D31: =B9 -> 18.128814 | E31: =B10 -> 4.1226415
A34: By priority
A35: Priority | B35: Tickets | C35: Share | D35: Avg hours
A36: Low | B36: =COUNTIFS(Cleaning!$E$2:$E$500,A36,Cleaning!$L$2:$L$500,1) -> 53 | C36: =IF($B$40=0,0,B36/$B$40) -> 0.35333333 | D36: =IFERROR(AVERAGEIFS(Cleaning!$G$2:$G$500,Cleaning!$E$2:$E$500,A36,Cleaning!$L$2:$L$500,1),0) -> 25.248718
A37: Medium | B37: =COUNTIFS(Cleaning!$E$2:$E$500,A37,Cleaning!$L$2:$L$500,1) -> 58 | C37: =IF($B$40=0,0,B37/$B$40) -> 0.38666667 | D37: =IFERROR(AVERAGEIFS(Cleaning!$G$2:$G$500,Cleaning!$E$2:$E$500,A37,Cleaning!$L$2:$L$500,1),0) -> 18.12449
A38: High | B38: =COUNTIFS(Cleaning!$E$2:$E$500,A38,Cleaning!$L$2:$L$500,1) -> 28 | C38: =IF($B$40=0,0,B38/$B$40) -> 0.18666667 | D38: =IFERROR(AVERAGEIFS(Cleaning!$G$2:$G$500,Cleaning!$E$2:$E$500,A38,Cleaning!$L$2:$L$500,1),0) -> 10.091667
A39: Urgent | B39: =COUNTIFS(Cleaning!$E$2:$E$500,A39,Cleaning!$L$2:$L$500,1) -> 11 | C39: =IF($B$40=0,0,B39/$B$40) -> 0.073333333 | D39: =IFERROR(AVERAGEIFS(Cleaning!$G$2:$G$500,Cleaning!$E$2:$E$500,A39,Cleaning!$L$2:$L$500,1),0) -> 4.0333333
A40: Total | B40: =SUM(B36:B39) -> 150 | C40: =SUM(C36:C39) -> 1 | D40: =B9 -> 18.128814

Sheet Report
B1: =Brief!C6 -> Monthly Customer Support Report
B2: ="Period: "&TEXT(Brief!C7,"d mmm yyyy")&" to "&TEXT(Brief!C8,"d mmm yyyy")&" | Audience: "&Brief!C9 -> Period: 1 Sep 2026 to 30 Sep 2026 | Audience: Head of Customer Support
B3: ="Prepared by "&Brief!C13&" | Data: helpdesk export (sample data)" -> Prepared by Your name | Data: helpdesk export (sample data)
B5: Executive summary
B6: =TEXT(Analysis!B4,"#,##0")&" tickets were handled in the period and "&TEXT(Analysis!B6,"0%")&" were resolved. Average resolution time was "&TEXT(Analysis!B9,"0.0")&" hours against a target of "&Brief!C18&" hours ("&IF(Analysis!B9<=Brief!C18,"on target","above target")&")." -> 150 tickets were handled in the period and 83% were resolved. Average resolution time was 18.1 hours against a target of 24 hours (on target).
B7: ="Customer satisfaction averaged "&TEXT(Analysis!B10,"0.0")&" out of 5, "&IF(Analysis!B10>=Brief!C19,"meeting","below")&" the target of "&TEXT(Brief!C19,"0.0")&"." -> Customer satisfaction averaged 4.1 out of 5, meeting the target of 4.0.
B8: =INDEX(Analysis!A16:A20,MATCH(MAX(Analysis!B16:B20),Analysis!B16:B20,0))&" was the biggest ticket category, with "&TEXT(MAX(Analysis!C16:C20),"0%")&" of all tickets." -> Billing was the biggest ticket category, with 41% of all tickets.
B10: Tickets | D10: Resolution rate | F10: Avg resolution (hrs) | H10: Avg satisfaction | J10: Escalated
B11: =Analysis!B4 -> 150 | D11: =Analysis!B6 -> 0.82666667 | F11: =Analysis!B9 -> 18.128814 | H11: =Analysis!B10 -> 4.1226415 | J11: =Analysis!B8 -> 11
B13: Ticket volume
B30: Agent performance and priority mix
B31: Agent | C31: Tickets | D31: Resolved | E31: Avg hours | F31: Avg CSAT | H31: Priority | I31: Tickets | J31: Share | K31: Avg hours
B32: =Analysis!A26 -> Maya Patel | C32: =Analysis!B26 -> 39 | D32: =Analysis!C26 -> 34 | E32: =Analysis!D26 -> 17.333333 | F32: =Analysis!E26 -> 4.1071429 | H32: =Analysis!A36 -> Low | I32: =Analysis!B36 -> 53 | J32: =Analysis!C36 -> 0.35333333 | K32: =Analysis!D36 -> 25.248718
B33: =Analysis!A27 -> Liam O'Brien | C33: =Analysis!B27 -> 23 | D33: =Analysis!C27 -> 21 | E33: =Analysis!D27 -> 14.875 | F33: =Analysis!E27 -> 4.2380952 | H33: =Analysis!A37 -> Medium | I33: =Analysis!B37 -> 58 | J33: =Analysis!C37 -> 0.38666667 | K33: =Analysis!D37 -> 18.12449
B34: =Analysis!A28 -> Sofia Rossi | C34: =Analysis!B28 -> 30 | D34: =Analysis!C28 -> 24 | E34: =Analysis!D28 -> 30.6 | F34: =Analysis!E28 -> 3.6842105 | H34: =Analysis!A38 -> High | I34: =Analysis!B38 -> 28 | J34: =Analysis!C38 -> 0.18666667 | K34: =Analysis!D38 -> 10.091667
B35: =Analysis!A29 -> Noah Kim | C35: =Analysis!B29 -> 31 | D35: =Analysis!C29 -> 24 | E35: =Analysis!D29 -> 16.320833 | F35: =Analysis!E29 -> 4.2857143 | H35: =Analysis!A39 -> Urgent | I35: =Analysis!B39 -> 11 | J35: =Analysis!C39 -> 0.073333333 | K35: =Analysis!D39 -> 4.0333333
B36: =Analysis!A30 -> Ava Johnson | C36: =Analysis!B30 -> 27 | D36: =Analysis!C30 -> 21 | E36: =Analysis!D30 -> 12.666667 | F36: =Analysis!E30 -> 4.2941176
B38: Key findings
B39: ="Busiest week: "&INDEX(Analysis!H5:H9,MATCH(MAX(Analysis!I5:I9),Analysis!I5:I9,0))&" with "&MAX(Analysis!I5:I9)&" tickets." -> Busiest week: 1 Sep - 7 Sep with 43 tickets.
B40: ="Fastest agent: "&INDEX(Analysis!A26:A30,MATCH(MIN(Analysis!D26:D30),Analysis!D26:D30,0))&" ("&TEXT(MIN(Analysis!D26:D30),"0.0")&" hours on average)." -> Fastest agent: Ava Johnson (12.7 hours on average).
B41: ="Highest satisfaction: "&INDEX(Analysis!A26:A30,MATCH(MAX(Analysis!E26:E30),Analysis!E26:E30,0))&" ("&TEXT(MAX(Analysis!E26:E30),"0.00")&" out of 5)." -> Highest satisfaction: Ava Johnson (4.29 out of 5).
B42: ="High and Urgent tickets made up "&TEXT(Analysis!B11,"0%")&" of volume." -> High and Urgent tickets made up 26% of volume.
B43: =(Analysis!B7+Analysis!B8)&" tickets were still open or escalated at the end of the period." -> 26 tickets were still open or escalated at the end of the period.
B45: Recommendations
B46: ="1. Review the "&INDEX(Analysis!A16:A20,MATCH(MAX(Analysis!B16:B20),Analysis!B16:B20,0))&" process. It creates the most tickets, so fixing its root causes gives the biggest drop in volume." -> 1. Review the Billing process. It creates the most tickets, so fixing its root causes gives the biggest drop in volume.
B47: =IF(Analysis!B9>Brief!C18,"2. Resolution time is above target. Learn from "&INDEX(Analysis!A26:A30,MATCH(MIN(Analysis!D26:D30),Analysis!D26:D30,0))&", the fastest agent, and share their approach.","2. Resolution time is within target. Keep current staffing and share the fastest agent's approach with the team.") -> 2. Resolution time is within target. Keep current staffing and share the fastest agent's approach with the team.
B48: ="3. Follow up the "&Analysis!B8&" escalated tickets and look for common causes." -> 3. Follow up the 11 escalated tickets and look for common causes.
B49: ="4. Ask the helpdesk team to fix the export: "&Checks!C7&" duplicates and "&(Checks!C9+Checks!C10)&" missing or impossible resolution times needed manual cleaning." -> 4. Ask the helpdesk team to fix the export: 6 duplicates and 6 missing or impossible resolution times needed manual cleaning.
B51: Notes on the data
B52: ="Cleaning applied: "&Checks!C7&" duplicate tickets excluded, "&Checks!C8&" text dates converted, "&Checks!C9&" missing and "&Checks!C10&" impossible resolution times left out of averages, "&Checks!C11&" resolved tickets had no satisfaction score." -> Cleaning applied: 6 duplicate tickets excluded, 10 text dates converted, 4 missing and 2 impossible resolution times left out of averages, 18 resolved tickets had no satisfaction score.
B53: Averages use only tickets that have a value. All figures come from sample data created for demonstration.
B55: ="Quality checks: "&Checks!C24 -> Quality checks: ALL CHECKS PASS
